nohup: ignoring input
[2024-05-09 13:53:31 +0800] [446687] [INFO] Starting gunicorn 20.1.0
[2024-05-09 13:53:31 +0800] [446687] [INFO] Listening at: http://10.206.0.13:8001 (446687)
[2024-05-09 13:53:31 +0800] [446687] [INFO] Using worker: gthread
[2024-05-09 13:53:31 +0800] [446688] [INFO] Booting worker with pid: 446688
[2024-05-09 13:53:31 +0800] [446689] [INFO] Booting worker with pid: 446689
/home/pengzai/anaconda3/envs/webserver/lib/python3.10/site-packages/huggingface_hub/file_download.py:1132: FutureWarning: `resume_download` is deprecated and will be removed in version 1.0.0. Downloads always resume when possible. If you want to force a new download, use `force_download=True`.
  warnings.warn(
/home/pengzai/anaconda3/envs/webserver/lib/python3.10/site-packages/huggingface_hub/file_download.py:1132: FutureWarning: `resume_download` is deprecated and will be removed in version 1.0.0. Downloads always resume when possible. If you want to force a new download, use `force_download=True`.
  warnings.warn(
[2024-05-09 13:53:44 +0800] [446689] [ERROR] Exception in worker process
Traceback (most recent call last):
  File "/home/pengzai/anaconda3/envs/webserver/lib/python3.10/site-packages/urllib3/connection.py", line 174, in _new_conn
    conn = connection.create_connection(
  File "/home/pengzai/anaconda3/envs/webserver/lib/python3.10/site-packages/urllib3/util/connection.py", line 95, in create_connection
    raise err
  File "/home/pengzai/anaconda3/envs/webserver/lib/python3.10/site-packages/urllib3/util/connection.py", line 85, in create_connection
    sock.connect(sa)
OSError: [Errno 101] Network is unreachable

During handling of the above exception, another exception occurred:

Traceback (most recent call last):
  File "/home/pengzai/anaconda3/envs/webserver/lib/python3.10/site-packages/urllib3/connectionpool.py", line 703, in urlopen
    httplib_response = self._make_request(
  File "/home/pengzai/anaconda3/envs/webserver/lib/python3.10/site-packages/urllib3/connectionpool.py", line 386, in _make_request
    self._validate_conn(conn)
  File "/home/pengzai/anaconda3/envs/webserver/lib/python3.10/site-packages/urllib3/connectionpool.py", line 1040, in _validate_conn
    conn.connect()
  File "/home/pengzai/anaconda3/envs/webserver/lib/python3.10/site-packages/urllib3/connection.py", line 358, in connect
    self.sock = conn = self._new_conn()
  File "/home/pengzai/anaconda3/envs/webserver/lib/python3.10/site-packages/urllib3/connection.py", line 186, in _new_conn
    raise NewConnectionError(
urllib3.exceptions.NewConnectionError: <urllib3.connection.HTTPSConnection object at 0x7fc350f7cee0>: Failed to establish a new connection: [Errno 101] Network is unreachable

During handling of the above exception, another exception occurred:

Traceback (most recent call last):
  File "/home/pengzai/anaconda3/envs/webserver/lib/python3.10/site-packages/requests/adapters.py", line 440, in send
    resp = conn.urlopen(
  File "/home/pengzai/anaconda3/envs/webserver/lib/python3.10/site-packages/urllib3/connectionpool.py", line 785, in urlopen
    retries = retries.increment(
  File "/home/pengzai/anaconda3/envs/webserver/lib/python3.10/site-packages/urllib3/util/retry.py", line 592, in increment
    raise MaxRetryError(_pool, url, error or ResponseError(cause))
urllib3.exceptions.MaxRetryError: HTTPSConnectionPool(host='huggingface.co', port=443): Max retries exceeded with url: /microsoft/swin-tiny-patch4-window7-224/resolve/main/config.json (Caused by NewConnectionError('<urllib3.connection.HTTPSConnection object at 0x7fc350f7cee0>: Failed to establish a new connection: [Errno 101] Network is unreachable'))

During handling of the above exception, another exception occurred:

Traceback (most recent call last):
  File "/home/pengzai/anaconda3/envs/webserver/lib/python3.10/site-packages/huggingface_hub/file_download.py", line 1722, in _get_metadata_or_catch_error
    metadata = get_hf_file_metadata(url=url, proxies=proxies, timeout=etag_timeout, headers=headers)
  File "/home/pengzai/anaconda3/envs/webserver/lib/python3.10/site-packages/huggingface_hub/utils/_validators.py", line 114, in _inner_fn
    return fn(*args, **kwargs)
  File "/home/pengzai/anaconda3/envs/webserver/lib/python3.10/site-packages/huggingface_hub/file_download.py", line 1645, in get_hf_file_metadata
    r = _request_wrapper(
  File "/home/pengzai/anaconda3/envs/webserver/lib/python3.10/site-packages/huggingface_hub/file_download.py", line 372, in _request_wrapper
    response = _request_wrapper(
  File "/home/pengzai/anaconda3/envs/webserver/lib/python3.10/site-packages/huggingface_hub/file_download.py", line 395, in _request_wrapper
    response = get_session().request(method=method, url=url, **params)
  File "/home/pengzai/anaconda3/envs/webserver/lib/python3.10/site-packages/requests/sessions.py", line 529, in request
    resp = self.send(prep, **send_kwargs)
  File "/home/pengzai/anaconda3/envs/webserver/lib/python3.10/site-packages/requests/sessions.py", line 645, in send
    r = adapter.send(request, **kwargs)
  File "/home/pengzai/anaconda3/envs/webserver/lib/python3.10/site-packages/huggingface_hub/utils/_http.py", line 66, in send
    return super().send(request, *args, **kwargs)
  File "/home/pengzai/anaconda3/envs/webserver/lib/python3.10/site-packages/requests/adapters.py", line 519, in send
    raise ConnectionError(e, request=request)
requests.exceptions.ConnectionError: (MaxRetryError("HTTPSConnectionPool(host='huggingface.co', port=443): Max retries exceeded with url: /microsoft/swin-tiny-patch4-window7-224/resolve/main/config.json (Caused by NewConnectionError('<urllib3.connection.HTTPSConnection object at 0x7fc350f7cee0>: Failed to establish a new connection: [Errno 101] Network is unreachable'))"), '(Request ID: 2c999f0b-2b61-4932-853c-5404d4348039)')

The above exception was the direct cause of the following exception:

Traceback (most recent call last):
  File "/home/pengzai/anaconda3/envs/webserver/lib/python3.10/site-packages/transformers/utils/hub.py", line 417, in cached_file
    resolved_file = hf_hub_download(
  File "/home/pengzai/anaconda3/envs/webserver/lib/python3.10/site-packages/huggingface_hub/utils/_validators.py", line 114, in _inner_fn
    return fn(*args, **kwargs)
  File "/home/pengzai/anaconda3/envs/webserver/lib/python3.10/site-packages/huggingface_hub/file_download.py", line 1221, in hf_hub_download
    return _hf_hub_download_to_cache_dir(
  File "/home/pengzai/anaconda3/envs/webserver/lib/python3.10/site-packages/huggingface_hub/file_download.py", line 1325, in _hf_hub_download_to_cache_dir
    _raise_on_head_call_error(head_call_error, force_download, local_files_only)
  File "/home/pengzai/anaconda3/envs/webserver/lib/python3.10/site-packages/huggingface_hub/file_download.py", line 1826, in _raise_on_head_call_error
    raise LocalEntryNotFoundError(
huggingface_hub.utils._errors.LocalEntryNotFoundError: An error happened while trying to locate the file on the Hub and we cannot find the requested files in the local cache. Please check your connection and try again or make sure your Internet connection is on.

During handling of the above exception, another exception occurred:

Traceback (most recent call last):
  File "/home/pengzai/anaconda3/envs/webserver/lib/python3.10/site-packages/gunicorn/arbiter.py", line 589, in spawn_worker
    worker.init_process()
  File "/home/pengzai/anaconda3/envs/webserver/lib/python3.10/site-packages/gunicorn/workers/gthread.py", line 92, in init_process
    super().init_process()
  File "/home/pengzai/anaconda3/envs/webserver/lib/python3.10/site-packages/gunicorn/workers/base.py", line 134, in init_process
    self.load_wsgi()
  File "/home/pengzai/anaconda3/envs/webserver/lib/python3.10/site-packages/gunicorn/workers/base.py", line 146, in load_wsgi
    self.wsgi = self.app.wsgi()
  File "/home/pengzai/anaconda3/envs/webserver/lib/python3.10/site-packages/gunicorn/app/base.py", line 67, in wsgi
    self.callable = self.load()
  File "/home/pengzai/anaconda3/envs/webserver/lib/python3.10/site-packages/gunicorn/app/wsgiapp.py", line 58, in load
    return self.load_wsgiapp()
  File "/home/pengzai/anaconda3/envs/webserver/lib/python3.10/site-packages/gunicorn/app/wsgiapp.py", line 48, in load_wsgiapp
    return util.import_app(self.app_uri)
  File "/home/pengzai/anaconda3/envs/webserver/lib/python3.10/site-packages/gunicorn/util.py", line 359, in import_app
    mod = importlib.import_module(module)
  File "/home/pengzai/anaconda3/envs/webserver/lib/python3.10/importlib/__init__.py", line 126, in import_module
    return _bootstrap._gcd_import(name[level:], package, level)
  File "<frozen importlib._bootstrap>", line 1050, in _gcd_import
  File "<frozen importlib._bootstrap>", line 1027, in _find_and_load
  File "<frozen importlib._bootstrap>", line 1006, in _find_and_load_unlocked
  File "<frozen importlib._bootstrap>", line 688, in _load_unlocked
  File "<frozen importlib._bootstrap_external>", line 883, in exec_module
  File "<frozen importlib._bootstrap>", line 241, in _call_with_frames_removed
  File "/var/www/html/ArtRate/ArtRate_server/ArtRate_server/wsgi.py", line 28, in <module>
    application = get_wsgi_application()
  File "/home/pengzai/anaconda3/envs/webserver/lib/python3.10/site-packages/django/core/wsgi.py", line 12, in get_wsgi_application
    django.setup(set_prefix=False)
  File "/home/pengzai/anaconda3/envs/webserver/lib/python3.10/site-packages/django/__init__.py", line 24, in setup
    apps.populate(settings.INSTALLED_APPS)
  File "/home/pengzai/anaconda3/envs/webserver/lib/python3.10/site-packages/django/apps/registry.py", line 91, in populate
    app_config = AppConfig.create(entry)
  File "/home/pengzai/anaconda3/envs/webserver/lib/python3.10/site-packages/django/apps/config.py", line 126, in create
    mod = import_module(mod_path)
  File "/home/pengzai/anaconda3/envs/webserver/lib/python3.10/importlib/__init__.py", line 126, in import_module
    return _bootstrap._gcd_import(name[level:], package, level)
  File "<frozen importlib._bootstrap>", line 1050, in _gcd_import
  File "<frozen importlib._bootstrap>", line 1027, in _find_and_load
  File "<frozen importlib._bootstrap>", line 1006, in _find_and_load_unlocked
  File "<frozen importlib._bootstrap>", line 688, in _load_unlocked
  File "<frozen importlib._bootstrap_external>", line 883, in exec_module
  File "<frozen importlib._bootstrap>", line 241, in _call_with_frames_removed
  File "/var/www/html/ArtRate/ArtRate_server/art/apps.py", line 30, in <module>
    art_net = ArtNet(args)
  File "/var/www/html/ArtRate/ArtRate_server/art/art_assessment_model.py", line 14, in __init__
    self.visual_net = VisualNet(args)
  File "/var/www/html/ArtRate/ArtRate_server/art/art_assessment_model.py", line 47, in __init__
    self.swim = SwinModel.from_pretrained('microsoft/swin-tiny-patch4-window7-224')
  File "/home/pengzai/anaconda3/envs/webserver/lib/python3.10/site-packages/transformers/modeling_utils.py", line 2251, in from_pretrained
    config, model_kwargs = cls.config_class.from_pretrained(
  File "/home/pengzai/anaconda3/envs/webserver/lib/python3.10/site-packages/transformers/configuration_utils.py", line 547, in from_pretrained
    config_dict, kwargs = cls.get_config_dict(pretrained_model_name_or_path, **kwargs)
  File "/home/pengzai/anaconda3/envs/webserver/lib/python3.10/site-packages/transformers/configuration_utils.py", line 574, in get_config_dict
    config_dict, kwargs = cls._get_config_dict(pretrained_model_name_or_path, **kwargs)
  File "/home/pengzai/anaconda3/envs/webserver/lib/python3.10/site-packages/transformers/configuration_utils.py", line 629, in _get_config_dict
    resolved_config_file = cached_file(
  File "/home/pengzai/anaconda3/envs/webserver/lib/python3.10/site-packages/transformers/utils/hub.py", line 452, in cached_file
    raise EnvironmentError(
OSError: We couldn't connect to 'https://huggingface.co' to load this file, couldn't find it in the cached files and it looks like microsoft/swin-tiny-patch4-window7-224 is not the path to a directory containing a file named config.json.
Checkout your internet connection or see how to run the library in offline mode at 'https://huggingface.co/docs/transformers/installation#offline-mode'.
[2024-05-09 13:53:44 +0800] [446688] [ERROR] Exception in worker process
Traceback (most recent call last):
  File "/home/pengzai/anaconda3/envs/webserver/lib/python3.10/site-packages/urllib3/connection.py", line 174, in _new_conn
    conn = connection.create_connection(
  File "/home/pengzai/anaconda3/envs/webserver/lib/python3.10/site-packages/urllib3/util/connection.py", line 95, in create_connection
    raise err
  File "/home/pengzai/anaconda3/envs/webserver/lib/python3.10/site-packages/urllib3/util/connection.py", line 85, in create_connection
    sock.connect(sa)
OSError: [Errno 101] Network is unreachable

During handling of the above exception, another exception occurred:

Traceback (most recent call last):
  File "/home/pengzai/anaconda3/envs/webserver/lib/python3.10/site-packages/urllib3/connectionpool.py", line 703, in urlopen
    httplib_response = self._make_request(
  File "/home/pengzai/anaconda3/envs/webserver/lib/python3.10/site-packages/urllib3/connectionpool.py", line 386, in _make_request
    self._validate_conn(conn)
  File "/home/pengzai/anaconda3/envs/webserver/lib/python3.10/site-packages/urllib3/connectionpool.py", line 1040, in _validate_conn
    conn.connect()
  File "/home/pengzai/anaconda3/envs/webserver/lib/python3.10/site-packages/urllib3/connection.py", line 358, in connect
    self.sock = conn = self._new_conn()
  File "/home/pengzai/anaconda3/envs/webserver/lib/python3.10/site-packages/urllib3/connection.py", line 186, in _new_conn
    raise NewConnectionError(
urllib3.exceptions.NewConnectionError: <urllib3.connection.HTTPSConnection object at 0x7fc350f7ce50>: Failed to establish a new connection: [Errno 101] Network is unreachable

During handling of the above exception, another exception occurred:

Traceback (most recent call last):
  File "/home/pengzai/anaconda3/envs/webserver/lib/python3.10/site-packages/requests/adapters.py", line 440, in send
    resp = conn.urlopen(
  File "/home/pengzai/anaconda3/envs/webserver/lib/python3.10/site-packages/urllib3/connectionpool.py", line 785, in urlopen
    retries = retries.increment(
  File "/home/pengzai/anaconda3/envs/webserver/lib/python3.10/site-packages/urllib3/util/retry.py", line 592, in increment
    raise MaxRetryError(_pool, url, error or ResponseError(cause))
urllib3.exceptions.MaxRetryError: HTTPSConnectionPool(host='huggingface.co', port=443): Max retries exceeded with url: /microsoft/swin-tiny-patch4-window7-224/resolve/main/config.json (Caused by NewConnectionError('<urllib3.connection.HTTPSConnection object at 0x7fc350f7ce50>: Failed to establish a new connection: [Errno 101] Network is unreachable'))

During handling of the above exception, another exception occurred:

Traceback (most recent call last):
  File "/home/pengzai/anaconda3/envs/webserver/lib/python3.10/site-packages/huggingface_hub/file_download.py", line 1722, in _get_metadata_or_catch_error
    metadata = get_hf_file_metadata(url=url, proxies=proxies, timeout=etag_timeout, headers=headers)
  File "/home/pengzai/anaconda3/envs/webserver/lib/python3.10/site-packages/huggingface_hub/utils/_validators.py", line 114, in _inner_fn
    return fn(*args, **kwargs)
  File "/home/pengzai/anaconda3/envs/webserver/lib/python3.10/site-packages/huggingface_hub/file_download.py", line 1645, in get_hf_file_metadata
    r = _request_wrapper(
  File "/home/pengzai/anaconda3/envs/webserver/lib/python3.10/site-packages/huggingface_hub/file_download.py", line 372, in _request_wrapper
    response = _request_wrapper(
  File "/home/pengzai/anaconda3/envs/webserver/lib/python3.10/site-packages/huggingface_hub/file_download.py", line 395, in _request_wrapper
    response = get_session().request(method=method, url=url, **params)
  File "/home/pengzai/anaconda3/envs/webserver/lib/python3.10/site-packages/requests/sessions.py", line 529, in request
    resp = self.send(prep, **send_kwargs)
  File "/home/pengzai/anaconda3/envs/webserver/lib/python3.10/site-packages/requests/sessions.py", line 645, in send
    r = adapter.send(request, **kwargs)
  File "/home/pengzai/anaconda3/envs/webserver/lib/python3.10/site-packages/huggingface_hub/utils/_http.py", line 66, in send
    return super().send(request, *args, **kwargs)
  File "/home/pengzai/anaconda3/envs/webserver/lib/python3.10/site-packages/requests/adapters.py", line 519, in send
    raise ConnectionError(e, request=request)
requests.exceptions.ConnectionError: (MaxRetryError("HTTPSConnectionPool(host='huggingface.co', port=443): Max retries exceeded with url: /microsoft/swin-tiny-patch4-window7-224/resolve/main/config.json (Caused by NewConnectionError('<urllib3.connection.HTTPSConnection object at 0x7fc350f7ce50>: Failed to establish a new connection: [Errno 101] Network is unreachable'))"), '(Request ID: d88c2eb1-e948-4d08-a55f-283e5ec07476)')

The above exception was the direct cause of the following exception:

Traceback (most recent call last):
  File "/home/pengzai/anaconda3/envs/webserver/lib/python3.10/site-packages/transformers/utils/hub.py", line 417, in cached_file
    resolved_file = hf_hub_download(
  File "/home/pengzai/anaconda3/envs/webserver/lib/python3.10/site-packages/huggingface_hub/utils/_validators.py", line 114, in _inner_fn
    return fn(*args, **kwargs)
  File "/home/pengzai/anaconda3/envs/webserver/lib/python3.10/site-packages/huggingface_hub/file_download.py", line 1221, in hf_hub_download
    return _hf_hub_download_to_cache_dir(
  File "/home/pengzai/anaconda3/envs/webserver/lib/python3.10/site-packages/huggingface_hub/file_download.py", line 1325, in _hf_hub_download_to_cache_dir
    _raise_on_head_call_error(head_call_error, force_download, local_files_only)
  File "/home/pengzai/anaconda3/envs/webserver/lib/python3.10/site-packages/huggingface_hub/file_download.py", line 1826, in _raise_on_head_call_error
    raise LocalEntryNotFoundError(
huggingface_hub.utils._errors.LocalEntryNotFoundError: An error happened while trying to locate the file on the Hub and we cannot find the requested files in the local cache. Please check your connection and try again or make sure your Internet connection is on.

During handling of the above exception, another exception occurred:

Traceback (most recent call last):
  File "/home/pengzai/anaconda3/envs/webserver/lib/python3.10/site-packages/gunicorn/arbiter.py", line 589, in spawn_worker
    worker.init_process()
  File "/home/pengzai/anaconda3/envs/webserver/lib/python3.10/site-packages/gunicorn/workers/gthread.py", line 92, in init_process
    super().init_process()
  File "/home/pengzai/anaconda3/envs/webserver/lib/python3.10/site-packages/gunicorn/workers/base.py", line 134, in init_process
    self.load_wsgi()
  File "/home/pengzai/anaconda3/envs/webserver/lib/python3.10/site-packages/gunicorn/workers/base.py", line 146, in load_wsgi
    self.wsgi = self.app.wsgi()
  File "/home/pengzai/anaconda3/envs/webserver/lib/python3.10/site-packages/gunicorn/app/base.py", line 67, in wsgi
    self.callable = self.load()
  File "/home/pengzai/anaconda3/envs/webserver/lib/python3.10/site-packages/gunicorn/app/wsgiapp.py", line 58, in load
    return self.load_wsgiapp()
  File "/home/pengzai/anaconda3/envs/webserver/lib/python3.10/site-packages/gunicorn/app/wsgiapp.py", line 48, in load_wsgiapp
    return util.import_app(self.app_uri)
  File "/home/pengzai/anaconda3/envs/webserver/lib/python3.10/site-packages/gunicorn/util.py", line 359, in import_app
    mod = importlib.import_module(module)
  File "/home/pengzai/anaconda3/envs/webserver/lib/python3.10/importlib/__init__.py", line 126, in import_module
    return _bootstrap._gcd_import(name[level:], package, level)
  File "<frozen importlib._bootstrap>", line 1050, in _gcd_import
  File "<frozen importlib._bootstrap>", line 1027, in _find_and_load
  File "<frozen importlib._bootstrap>", line 1006, in _find_and_load_unlocked
  File "<frozen importlib._bootstrap>", line 688, in _load_unlocked
  File "<frozen importlib._bootstrap_external>", line 883, in exec_module
  File "<frozen importlib._bootstrap>", line 241, in _call_with_frames_removed
  File "/var/www/html/ArtRate/ArtRate_server/ArtRate_server/wsgi.py", line 28, in <module>
    application = get_wsgi_application()
  File "/home/pengzai/anaconda3/envs/webserver/lib/python3.10/site-packages/django/core/wsgi.py", line 12, in get_wsgi_application
    django.setup(set_prefix=False)
  File "/home/pengzai/anaconda3/envs/webserver/lib/python3.10/site-packages/django/__init__.py", line 24, in setup
    apps.populate(settings.INSTALLED_APPS)
  File "/home/pengzai/anaconda3/envs/webserver/lib/python3.10/site-packages/django/apps/registry.py", line 91, in populate
    app_config = AppConfig.create(entry)
  File "/home/pengzai/anaconda3/envs/webserver/lib/python3.10/site-packages/django/apps/config.py", line 126, in create
    mod = import_module(mod_path)
  File "/home/pengzai/anaconda3/envs/webserver/lib/python3.10/importlib/__init__.py", line 126, in import_module
    return _bootstrap._gcd_import(name[level:], package, level)
  File "<frozen importlib._bootstrap>", line 1050, in _gcd_import
  File "<frozen importlib._bootstrap>", line 1027, in _find_and_load
  File "<frozen importlib._bootstrap>", line 1006, in _find_and_load_unlocked
  File "<frozen importlib._bootstrap>", line 688, in _load_unlocked
  File "<frozen importlib._bootstrap_external>", line 883, in exec_module
  File "<frozen importlib._bootstrap>", line 241, in _call_with_frames_removed
  File "/var/www/html/ArtRate/ArtRate_server/art/apps.py", line 30, in <module>
    art_net = ArtNet(args)
  File "/var/www/html/ArtRate/ArtRate_server/art/art_assessment_model.py", line 14, in __init__
    self.visual_net = VisualNet(args)
  File "/var/www/html/ArtRate/ArtRate_server/art/art_assessment_model.py", line 47, in __init__
    self.swim = SwinModel.from_pretrained('microsoft/swin-tiny-patch4-window7-224')
  File "/home/pengzai/anaconda3/envs/webserver/lib/python3.10/site-packages/transformers/modeling_utils.py", line 2251, in from_pretrained
    config, model_kwargs = cls.config_class.from_pretrained(
  File "/home/pengzai/anaconda3/envs/webserver/lib/python3.10/site-packages/transformers/configuration_utils.py", line 547, in from_pretrained
    config_dict, kwargs = cls.get_config_dict(pretrained_model_name_or_path, **kwargs)
  File "/home/pengzai/anaconda3/envs/webserver/lib/python3.10/site-packages/transformers/configuration_utils.py", line 574, in get_config_dict
    config_dict, kwargs = cls._get_config_dict(pretrained_model_name_or_path, **kwargs)
  File "/home/pengzai/anaconda3/envs/webserver/lib/python3.10/site-packages/transformers/configuration_utils.py", line 629, in _get_config_dict
    resolved_config_file = cached_file(
  File "/home/pengzai/anaconda3/envs/webserver/lib/python3.10/site-packages/transformers/utils/hub.py", line 452, in cached_file
    raise EnvironmentError(
OSError: We couldn't connect to 'https://huggingface.co' to load this file, couldn't find it in the cached files and it looks like microsoft/swin-tiny-patch4-window7-224 is not the path to a directory containing a file named config.json.
Checkout your internet connection or see how to run the library in offline mode at 'https://huggingface.co/docs/transformers/installation#offline-mode'.
[2024-05-09 13:53:44 +0800] [446689] [INFO] Worker exiting (pid: 446689)
[2024-05-09 13:53:44 +0800] [446688] [INFO] Worker exiting (pid: 446688)
Traceback (most recent call last):
  File "/home/pengzai/anaconda3/envs/webserver/lib/python3.10/site-packages/gunicorn/arbiter.py", line 209, in run
    self.sleep()
  File "/home/pengzai/anaconda3/envs/webserver/lib/python3.10/site-packages/gunicorn/arbiter.py", line 357, in sleep
    ready = select.select([self.PIPE[0]], [], [], 1.0)
  File "/home/pengzai/anaconda3/envs/webserver/lib/python3.10/site-packages/gunicorn/arbiter.py", line 242, in handle_chld
    self.reap_workers()
  File "/home/pengzai/anaconda3/envs/webserver/lib/python3.10/site-packages/gunicorn/arbiter.py", line 525, in reap_workers
    raise HaltServer(reason, self.WORKER_BOOT_ERROR)
gunicorn.errors.HaltServer: <HaltServer 'Worker failed to boot.' 3>

During handling of the above exception, another exception occurred:

Traceback (most recent call last):
  File "/home/pengzai/anaconda3/envs/webserver/bin/gunicorn", line 8, in <module>
    sys.exit(run())
  File "/home/pengzai/anaconda3/envs/webserver/lib/python3.10/site-packages/gunicorn/app/wsgiapp.py", line 67, in run
    WSGIApplication("%(prog)s [OPTIONS] [APP_MODULE]").run()
  File "/home/pengzai/anaconda3/envs/webserver/lib/python3.10/site-packages/gunicorn/app/base.py", line 231, in run
    super().run()
  File "/home/pengzai/anaconda3/envs/webserver/lib/python3.10/site-packages/gunicorn/app/base.py", line 72, in run
    Arbiter(self).run()
  File "/home/pengzai/anaconda3/envs/webserver/lib/python3.10/site-packages/gunicorn/arbiter.py", line 229, in run
    self.halt(reason=inst.reason, exit_status=inst.exit_status)
  File "/home/pengzai/anaconda3/envs/webserver/lib/python3.10/site-packages/gunicorn/arbiter.py", line 342, in halt
    self.stop()
  File "/home/pengzai/anaconda3/envs/webserver/lib/python3.10/site-packages/gunicorn/arbiter.py", line 393, in stop
    time.sleep(0.1)
  File "/home/pengzai/anaconda3/envs/webserver/lib/python3.10/site-packages/gunicorn/arbiter.py", line 242, in handle_chld
    self.reap_workers()
  File "/home/pengzai/anaconda3/envs/webserver/lib/python3.10/site-packages/gunicorn/arbiter.py", line 525, in reap_workers
    raise HaltServer(reason, self.WORKER_BOOT_ERROR)
gunicorn.errors.HaltServer: <HaltServer 'Worker failed to boot.' 3>
